Workbook

Sheet Foglio7
A3: Media di Sales | B3: Customer Segment
A4: Order Date | B4: Consumer | C4: Corporate | D4: Home Office | E4: Small Business | F4: Totale Risultato
A5: 43101 | B5: 1313.08 | C5: 3248.3275 | F5: 2861.278
A6: 43132 | C6: 1309.07 | D6: 155.38 | E6: 329.08333 | F6: 394.63714
A7: 43160 | B7: 450.86 | C7: 4114.8 | E7: 625.525 | F7: 1986.302
A8: 43191 | C8: 207.63 | F8: 207.63
A9: 43221 | C9: 3531.6314 | F9: 3531.6314
A10: 43252 | C10: 826.33 | D10: 5181.16 | E10: 115 | F10: 1559.3725
A11: 43282 | B11: 4599.37 | E11: 734.796 | F11: 1838.96
A12: 43313 | C12: 140.58 | E12: 5255.02 | F12: 2697.8
A13: 43344 | B13: 998.19 | C13: 2549.056 | F13: 2290.5783
A14: 43374 | B14: 163.96 | C14: 4275.8283 | D14: 75.87 | F14: 3236.85
A15: 43405 | C15: 313.8 | D15: 1357.535 | E15: 4617.735 | F15: 2452.868
A16: 43435 | B16: 3809.695 | C16: 567.1475 | F16: 1647.9967
A17: 43102 | B17: 859.775 | C17: 1542.52 | D17: 1673.65 | F17: 1233.93
A18: 43133 | B18: 1733.2333 | C18: 811.085 | D18: 318.99 | F18: 1190.1433
A19: 43161 | B19: 472.73 | D19: 439.085 | E19: 694.92 | F19: 511.455
A20: 43192 | B20: 2349.78 | C20: 180.97 | D20: 97.83 | F20: 1612.9867
A21: 43222 | B21: 758.93375 | C21: 160.85 | D21: 847.075 | F21: 720.58818
A22: 43253 | B22: 184.17333 | D22: 863.43333 | E22: 2109.95 | F22: 920.34
A23: 43283 | B23: 7675.85 | C23: 647.7 | D23: 5405.52 | E23: 121.01 | F23: 3882.073
A24: 43314 | B24: 314.08667 | C24: 974.75 | D24: 446.76 | F24: 472.754
A25: 43345 | B25: 260.865 | C25: 1349.5933 | D25: 1009.37 | F25: 949.8275
A26: 43375 | B26: 7333.7767 | C26: 1582.68 | D26: 1478.1986 | F26: 3084.6727
A27: 43406 | C27: 545.15 | D27: 498.99 | E27: 3562.32 | F27: 1535.4867
A28: 43436 | B28: 660.42 | C28: 2083.75 | D28: 33.555 | E28: 135.43 | F28: 589.342
A29: 43103 | B29: 120.005 | C29: 2019.924 | D29: 6692.39 | F29: 2178.5836
A30: 43134 | B30: 177.1 | C30: 2632.2933 | F30: 2018.495
A31: 43162 | B31: 826.305 | C31: 3069.8075 | D31: 5933.14 | E31: 145.245 | F31: 2239.4967
A32: 43193 | D32: 2667.5533 | F32: 2667.5533
A33: 43223 | B33: 1574.4283 | C33: 602.215 | D33: 225.62 | F33: 1208.5133
A34: 43254 | E34: 79.23 | F34: 79.23
A35: 43284 | C35: 514.365 | D35: 2314.21 | E35: 211.39 | F35: 701.47375
A36: 43315 | D36: 8793.43 | E36: 566.56 | F36: 3308.85
A37: 43346 | B37: 210.77 | C37: 3115.86 | D37: 36.34 | E37: 11182.46 | F37: 5145.578
A38: 43376 | C38: 93.99 | E38: 505.945 | F38: 299.9675
A39: 43437 | C39: 632.7 | D39: 3607.08 | F39: 2119.89
A40: 43104 | D40: 550.77 | F40: 550.77
A41: 43135 | B41: 87.5 | C41: 9399.86 | D41: 1812.1725 | E41: 896.265 | F41: 3103.16
A42: 43163 | C42: 2406.605 | D42: 6540.8167 | F42: 4178.41
...

Sheet Compiled Information
E1: 4 | F1: 5 | G1: 6
A2: Unique ID | B2: Order Date | C2: Ship Date | D2: Shipping Cost | E2: Order Quantity | F2: Sales | G2: Customer Segment
A3: 1020 | B3: Order Date | C3: 43125 | D3: =VLOOKUP(A3,'Order Shipping'!$A$2:$C$2000,3,FALSE()) -> 0.5 | E3: =VLOOKUP($A3,'Order Sales'!$A$2:$G$2154,E$1,FALSE()) -> 4 | F3: =VLOOKUP($A3,'Order Sales'!$A$2:$G$2154,F$1,FALSE()) -> 16.01 | G3: =VLOOKUP($A3,'Order Sales'!$A$2:$G$2154,G$1,FALSE()) -> Corporate
A4: 1863 | B4: Order Date | C4: 43126 | D4: =VLOOKUP(A4,'Order Shipping'!$A$2:$C$2000,3,FALSE()) -> 5.9 | E4: =VLOOKUP($A4,'Order Sales'!$A$2:$G$2154,E$1,FALSE()) -> 20 | F4: =VLOOKUP($A4,'Order Sales'!$A$2:$G$2154,F$1,FALSE()) -> 706.49 | G4: =VLOOKUP($A4,'Order Sales'!$A$2:$G$2154,G$1,FALSE()) -> Home Office
A5: 1153 | B5: Order Date | C5: 43127 | D5: =VLOOKUP(A5,'Order Shipping'!$A$2:$C$2000,3,FALSE()) -> 3.9 | E5: =VLOOKUP($A5,'Order Sales'!$A$2:$G$2154,E$1,FALSE()) -> 20 | F5: =VLOOKUP($A5,'Order Sales'!$A$2:$G$2154,F$1,FALSE()) -> 163.11 | G5: =VLOOKUP($A5,'Order Sales'!$A$2:$G$2154,G$1,FALSE()) -> Corporate
A6: 1223 | B6: Order Date | C6: 43128 | D6: =VLOOKUP(A6,'Order Shipping'!$A$2:$C$2000,3,FALSE()) -> 10.9 | E6: =VLOOKUP($A6,'Order Sales'!$A$2:$G$2154,E$1,FALSE()) -> 14 | F6: =VLOOKUP($A6,'Order Sales'!$A$2:$G$2154,F$1,FALSE()) -> 781.45 | G6: =VLOOKUP($A6,'Order Sales'!$A$2:$G$2154,G$1,FALSE()) -> Small Business
A7: 3002 | B7: Order Date | C7: 43129 | D7: =VLOOKUP(A7,'Order Shipping'!$A$2:$C$2000,3,FALSE()) -> 15.7 | E7: =VLOOKUP($A7,'Order Sales'!$A$2:$G$2154,E$1,FALSE()) -> 29 | F7: =VLOOKUP($A7,'Order Sales'!$A$2:$G$2154,F$1,FALSE()) -> 11812.53 | G7: =VLOOKUP($A7,'Order Sales'!$A$2:$G$2154,G$1,FALSE()) -> Small Business
A8: 2857 | B8: Order Date | C8: 43130 | D8: =VLOOKUP(A8,'Order Shipping'!$A$2:$C$2000,3,FALSE()) -> 1.3 | E8: =VLOOKUP($A8,'Order Sales'!$A$2:$G$2154,E$1,FALSE()) -> 20 | F8: =VLOOKUP($A8,'Order Sales'!$A$2:$G$2154,F$1,FALSE()) -> 1529.12 | G8: =VLOOKUP($A8,'Order Sales'!$A$2:$G$2154,G$1,FALSE()) -> Small Business
A9: 1431 | B9: Order Date | C9: 43131 | D9: =VLOOKUP(A9,'Order Shipping'!$A$2:$C$2000,3,FALSE()) -> 4.3 | E9: =VLOOKUP($A9,'Order Sales'!$A$2:$G$2154,E$1,FALSE()) -> 6 | F9: =VLOOKUP($A9,'Order Sales'!$A$2:$G$2154,F$1,FALSE()) -> 136.41 | G9: =VLOOKUP($A9,'Order Sales'!$A$2:$G$2154,G$1,FALSE()) -> Corporate
A10: 1650 | B10: Order Date | C10: 43132 | D10: =VLOOKUP(A10,'Order Shipping'!$A$2:$C$2000,3,FALSE()) -> 10 | E10: =VLOOKUP($A10,'Order Sales'!$A$2:$G$2154,E$1,FALSE()) -> 30 | F10: =VLOOKUP($A10,'Order Sales'!$A$2:$G$2154,F$1,FALSE()) -> 424.36 | G10: =VLOOKUP($A10,'Order Sales'!$A$2:$G$2154,G$1,FALSE()) -> Corporate
A11: 2861 | B11: Order Date | C11: 43133 | D11: =VLOOKUP(A11,'Order Shipping'!$A$2:$C$2000,3,FALSE()) -> 5.6 | E11: =VLOOKUP($A11,'Order Sales'!$A$2:$G$2154,E$1,FALSE()) -> 23 | F11: =VLOOKUP($A11,'Order Sales'!$A$2:$G$2154,F$1,FALSE()) -> 167.63 | G11: =VLOOKUP($A11,'Order Sales'!$A$2:$G$2154,G$1,FALSE()) -> Small Business
A12: 2609 | B12: Order Date | C12: 43134 | D12: =VLOOKUP(A12,'Order Shipping'!$A$2:$C$2000,3,FALSE()) -> 3 | E12: =VLOOKUP($A12,'Order Sales'!$A$2:$G$2154,E$1,FALSE()) -> 8 | F12: =VLOOKUP($A12,'Order Sales'!$A$2:$G$2154,F$1,FALSE()) -> 100.95 | G12: =VLOOKUP($A12,'Order Sales'!$A$2:$G$2154,G$1,FALSE()) -> Corporate
A13: 1802 | B13: Order Date | C13: 43135 | D13: =VLOOKUP(A13,'Order Shipping'!$A$2:$C$2000,3,FALSE()) -> 0.7 | E13: =VLOOKUP($A13,'Order Sales'!$A$2:$G$2154,E$1,FALSE()) -> 14 | F13: =VLOOKUP($A13,'Order Sales'!$A$2:$G$2154,F$1,FALSE()) -> 28.95 | G13: =VLOOKUP($A13,'Order Sales'!$A$2:$G$2154,G$1,FALSE()) -> Consumer
A14: 2344 | B14: Order Date | C14: 43136 | D14: =VLOOKUP(A14,'Order Shipping'!$A$2:$C$2000,3,FALSE()) -> 9.6 | E14: =VLOOKUP($A14,'Order Sales'!$A$2:$G$2154,E$1,FALSE()) -> 43 | F14: =VLOOKUP($A14,'Order Sales'!$A$2:$G$2154,F$1,FALSE()) -> 1330.95 | G14: =VLOOKUP($A14,'Order Sales'!$A$2:$G$2154,G$1,FALSE()) -> Corporate
... A106: 2078 | B106: Order Date | C106: 43228 | D106: =VLOOKUP(A106,'Order Shipping'!$A$2:$C$2000,3,FALSE()) -> 80.5 | E106: =VLOOKUP($A106,'Order Sales'!$A$2:$G$2154,E$1,FALSE()) -> 41 | F106: =VLOOKUP($A106,'Order Sales'!$A$2:$G$2154,F$1,FALSE()) -> 18670.16 | G106: =VLOOKUP($A106,'Order Sales'!$A$2:$G$2154,G$1,FALSE()) -> Consumer
A107: 1251 | B107: 43220 | C107: 43229 | D107: =VLOOKUP(A107,'Order Shipping'!$A$2:$C$2000,3,FALSE()) -> 3.6 | E107: =VLOOKUP($A107,'Order Sales'!$A$2:$G$2154,E$1,FALSE()) -> 42 | F107: =VLOOKUP($A107,'Order Sales'!$A$2:$G$2154,F$1,FALSE()) -> 274.6 | G107: =VLOOKUP($A107,'Order Sales'!$A$2:$G$2154,G$1,FALSE()) -> Corporate
A108: 2893 | B108: 43307 | C108: 43230 | D108: =VLOOKUP(A108,'Order Shipping'!$A$2:$C$2000,3,FALSE()) -> 0.7 | E108: =VLOOKUP($A108,'Order Sales'!$A$2:$G$2154,E$1,FALSE()) -> 37 | F108: =VLOOKUP($A108,'Order Sales'!$A$2:$G$2154,F$1,FALSE()) -> 119.19 | G108: =VLOOKUP($A108,'Order Sales'!$A$2:$G$2154,G$1,FALSE()) -> Corporate
A109: 2818 | B109: 43339 | C109: 43231 | D109: =VLOOKUP(A109,'Order Shipping'!$A$2:$C$2000,3,FALSE()) -> 6.7 | E109: =VLOOKUP($A109,'Order Sales'!$A$2:$G$2154,E$1,FALSE()) -> 7 | F109: =VLOOKUP($A109,'Order Sales'!$A$2:$G$2154,F$1,FALSE()) -> 96.92 | G109: =VLOOKUP($A109,'Order Sales'!$A$2:$G$2154,G$1,FALSE()) -> Small Business
A110: 1184 | B110: 43222 | C110: 43232 | D110: =VLOOKUP(A110,'Order Shipping'!$A$2:$C$2000,3,FALSE()) -> 21.4 | E110: =VLOOKUP($A110,'Order Sales'!$A$2:$G$2154,E$1,FALSE()) -> 4 | F110: =VLOOKUP($A110,'Order Sales'!$A$2:$G$2154,F$1,FALSE()) -> 2360.6 | G110: =VLOOKUP($A110,'Order Sales'!$A$2:$G$2154,G$1,FALSE()) -> Consumer
A111: 1954 | B111: 43191 | C111: 43233 | D111: =VLOOKUP(A111,'Order Shipping'!$A$2:$C$2000,3,FALSE()) -> 52.4 | E111: =VLOOKUP($A111,'Order Sales'!$A$2:$G$2154,E$1,FALSE()) -> 14 | F111: =VLOOKUP($A111,'Order Sales'!$A$2:$G$2154,F$1,FALSE()) -> 104.79 | G111: =VLOOKUP($A111,'Order Sales'!$A$2:$G$2154,G$1,FALSE()) -> Corporate
A112: 1878 | B112: 43455 | C112: 43234 | D112: =VLOOKUP(A112,'Order Shipping'!$A$2:$C$2000,3,FALSE()) -> 5.6 | E112: =VLOOKUP($A112,'Order Sales'!$A$2:$G$2154,E$1,FALSE()) -> 17 | F112: =VLOOKUP($A112,'Order Sales'!$A$2:$G$2154,F$1,FALSE()) -> 77.84 | G112: =VLOOKUP($A112,'Order Sales'!$A$2:$G$2154,G$1,FALSE()) -> Small Business
A113: 1038 | B113: 43295 | C113: 43235 | D113: =VLOOKUP(A113,'Order Shipping'!$A$2:$C$2000,3,FALSE()) -> 0.5 | E113: =VLOOKUP($A113,'Order Sales'!$A$2:$G$2154,E$1,FALSE()) -> 6 | F113: =VLOOKUP($A113,'Order Sales'!$A$2:$G$2154,F$1,FALSE()) -> 29.97 | G113: =VLOOKUP($A113,'Order Sales'!$A$2:$G$2154,G$1,FALSE()) -> Corporate
A114: 2792 | B114: 43322 | C114: 43236 | D114: =VLOOKUP(A114,'Order Shipping'!$A$2:$C$2000,3,FALSE()) -> 38.6 | E114: =VLOOKUP($A114,'Order Sales'!$A$2:$G$2154,E$1,FALSE()) -> 23 | F114: =VLOOKUP($A114,'Order Sales'!$A$2:$G$2154,F$1,FALSE()) -> 3532.42 | G114: =VLOOKUP($A114,'Order Sales'!$A$2:$G$2154,G$1,FALSE()) -> Corporate
A115: 2836 | B115: 43404 | C115: 43237 | D115: =VLOOKUP(A115,'Order Shipping'!$A$2:$C$2000,3,FALSE()) -> 8.2 | E115: =VLOOKUP($A115,'Order Sales'!$A$2:$G$2154,E$1,FALSE()) -> 42 | F115: =VLOOKUP($A115,'Order Sales'!$A$2:$G$2154,F$1,FALSE()) -> 4680.02 | G115: =VLOOKUP($A115,'Order Sales'!$A$2:$G$2154,G$1,FALSE()) -> Corporate
A116: 1793 | B116: 43371 | C116: 43238 | D116: =VLOOKUP(A116,'Order Shipping'!$A$2:$C$2000,3,FALSE()) -> 3.7 | E116: =VLOOKUP($A116,'Order Sales'!$A$2:$G$2154,E$1,FALSE()) -> 37 | F116: =VLOOKUP($A116,'Order Sales'!$A$2:$G$2154,F$1,FALSE()) -> 1708.64 | G116: =VLOOKUP($A116,'Order Sales'!$A$2:$G$2154,G$1,FALSE()) -> Corporate
A117: 2709 | B117: 43177 | C117: 43239 | D117: =VLOOKUP(A117,'Order Shipping'!$A$2:$C$2000,3,FALSE()) -> 1 | E117: =VLOOKUP($A117,'Order Sales'!$A$2:$G$2154,E$1,FALSE()) -> 35 | F117: =VLOOKUP($A117,'Order Sales'!$A$2:$G$2154,F$1,FALSE()) -> 142.38 | G117: =VLOOKUP($A117,'Order Sales'!$A$2:$G$2154,G$1,FALSE()) -> Corporate
A118: 2981 | B118: 43379 | C118: 43240 | D118: =VLOOKUP(A118,'Order Shipping'!$A$2:$C$2000,3,FALSE()) -> 9.6 | E118: =VLOOKUP($A118,'Order Sales'!$A$2:$G$2154,E$1,FALSE()) -> 39 | F118: =VLOOKUP($A118,'Order Sales'!$A$2:$G$2154,F$1,FALSE()) -> 4510.94 | G118: =VLOOKUP($A118,'Order Sales'!$A$2:$G$2154,G$1,FALSE()) -> Corporate
... A2001: 1470 | B2001: 43245 | C2001: 45123 | D2001: =VLOOKUP(A2001,'Order Shipping'!$A$2:$C$2000,3,FALSE()) -> 8 | E2001: =VLOOKUP($A2001,'Order Sales'!$A$2:$G$2154,E$1,FALSE()) -> 42 | F2001: =VLOOKUP($A2001,'Order Sales'!$A$2:$G$2154,F$1,FALSE()) -> 306.8 | G2001: =VLOOKUP($A2001,'Order Sales'!$A$2:$G$2154,G$1,FALSE()) -> Corporate

Sheet Tabella pivot_Compiled Informat
A1: Order Date | B1: Somma - Sales | C1: Anno | D1: Mese
A2: 43101 | B2: 14306.39 | C2: =YEAR(A2) -> 2018 | D2: =MONTH(A2) -> 1
A3: 43132 | B3: 2762.46 | C3: =YEAR(A3) -> 2018 | D3: =MONTH(A3) -> 2
A4: 43160 | B4: 9931.51 | C4: =YEAR(A4) -> 2018 | D4: =MONTH(A4) -> 3
A5: 43191 | B5: 1661.04 | C5: =YEAR(A5) -> 2018 | D5: =MONTH(A5) -> 4
A6: 43221 | B6: 24721.42 | C6: =YEAR(A6) -> 2018 | D6: =MONTH(A6) -> 5
A7: 43252 | B7: 6237.49 | C7: =YEAR(A7) -> 2018 | D7: =MONTH(A7) -> 6
A8: 43282 | B8: 12872.72 | C8: =YEAR(A8) -> 2018 | D8: =MONTH(A8) -> 7
A9: 43313 | B9: 10791.2 | C9: =YEAR(A9) -> 2018 | D9: =MONTH(A9) -> 8
A10: 43344 | B10: 13743.47 | C10: =YEAR(A10) -> 2018 | D10: =MONTH(A10) -> 9
A11: 43374 | B11: 25894.8 | C11: =YEAR(A11) -> 2018 | D11: =MONTH(A11) -> 10
A12: 43405 | B12: 12264.34 | C12: =YEAR(A12) -> 2018 | D12: =MONTH(A12) -> 11
A13: 43435 | B13: 9887.98 | C13: =YEAR(A13) -> 2018 | D13: =MONTH(A13) -> 12
... A355: 43465 | B355: 2720.67 | C355: =YEAR(A355) -> 2018 | D355: =MONTH(A355) -> 12
A356: Order Date | B356: 204070.14 | C356: =YEAR(A356) -> #VALUE! | D356: =MONTH(A356) -> #VALUE!
A357: Totale Risultato | B357: 3677748.5 | C357: =YEAR(A357) -> #VALUE! | D357: =MONTH(A357) -> #VALUE!
A359: Somma - Somma - Sales | B359: Mese
A360: Anno | B360: 1 | C360: 2 | D360: 3 | E360: 4 | F360: 5 | G360: 6 | H360: 7 | I360: 8 | J360: 9 | K360: 10 | L360: 11 | M360: 12 | N360: #VALORE! | O360: Totale Risultato
A361: 2018 | B361: 267858.22 | C361: 291238.48 | D361: 300730.17 | E361: 308534.72 | F361: 274493.05 | G361: 199184.15 | H361: 300105.36 | I361: 279880.54 | J361: 267275.98 | K361: 315096.61 | L361: 338332.88 | M361: 330948.24 | O361: 3473678.4
A362: #VALORE! | N362: 3881818.7 | O362: 3881818.7
A363: Totale Risultato | B363: 267858.22 | C363: 291238.48 | D363: 300730.17 | E363: 308534.72 | F363: 274493.05 | G363: 199184.15 | H363: 300105.36 | I363: 279880.54 | J363: 267275.98 | K363: 315096.61 | L363: 338332.88 | M363: 330948.24 | N363: 3881818.7 | O363: 7355497.1

Sheet Order Sales
A1: Unique ID | B1: Order Date | C1: Order Priority | D1: Order Quantity | E1: Sales | F1: Customer Segment | G1: Product Category | H1: Product Sub-Category
A2: 1005 | B2: 43295 | C2: High | D2: 26 | E2: 3004.65 | F2: Corporate | G2: Furniture | H2: Office Furnishings
A3: 1006 | B3: 43295 | C3: High | D3: 23 | E3: 171.45 | F3: Corporate | G3: Technology | H3: Telephones and Communication
A4: 1007 | B4: 43295 | C4: High | D4: 15 | E4: 150.4 | F4: Corporate | G4: Technology | H4: Computer Peripherals
A5: 1008 | B5: 43295 | C5: High | D5: 24 | E5: 1884.7 | F5: Corporate | G5: Furniture | H5: Tables
A6: 1009 | B6: 43394 | C6: Not Specified | D6: 30 | E6: 308.76 | F6: Corporate | G6: Office Supplies | H6: Pens & Art Supplies
A7: 1010 | B7: 43394 | C7: Not Specified | D7: 14 | E7: 2025.35 | F7: Corporate | G7: Technology | H7: Telephones and Communication
A8: 1011 | B8: 43405 | C8: Critical | D8: 46 | E8: 2658.68 | F8: Home Office | G8: Technology | H8: Telephones and Communication
A9: 1012 | B9: 43175 | C9: Critical | D9: 32 | E9: 4079.62 | F9: Corporate | G9: Technology | H9: Computer Peripherals
A10: 1013 | B10: 43392 | C10: Not Specified | D10: 25 | E10: 134.66 | F10: Consumer | G10: Technology | H10: Computer Peripherals
A11: 1014 | B11: 43353 | C11: High | D11: 10 | E11: 607.69 | F11: Consumer | G11: Technology | H11: Telephones and Communication
A12: 1015 | B12: 43195 | C12: High | D12: 23 | E12: 332.26 | F12: Home Office | G12: Office Supplies | H12: Scissors, Rulers and Trimmers
A13: 1016 | B13: 43243 | C13: Critical | D13: 1 | E13: 25.36 | F13: Home Office | G13: Office Supplies | H13: Pens & Art Supplies
... A2000: 3003 | B2000: 43418 | C2000: Low | D2000: 30 | E2000: 5331.75 | F2000: Small Business | G2000: Furniture | H2000: Tables

Sheet Order Shipping
A1: Unique ID | B1: Ship Mode | C1: Shipping Cost | D1: Province | E1: Product Container
A2: 1005 | B2: Regular Air | C2: 6.2 | D2: Alberta | E2: Medium Box
A3: 1006 | B3: Regular Air | C3: 5.4 | D3: Alberta | E3: Medium Box
A4: 1007 | B4: Regular Air | C4: 9.6 | D4: Saskachewan | E4: Small Pack
A5: 1008 | B5: Delivery Truck | C5: 95.6 | D5: Alberta | E5: Jumbo Box
A6: 1009 | B6: Regular Air | C6: 2.4 | D6: British Columbia | E6: Wrap Bag
A7: 1010 | B7: Regular Air | C7: 9.6 | D7: British Columbia | E7: Small Box
A8: 1011 | B8: Regular Air | C8: 4.5 | D8: Alberta | E8: Small Box
A9: 1012 | B9: Regular Air | C9: 2.1 | D9: Ontario | E9: Small Pack
A10: 1013 | B10: Regular Air | C10: 4.9 | D10: Quebec | E10: Small Pack
A11: 1014 | B11: Express Air | C11: 9.6 | D11: Manitoba | E11: Small Box
A12: 1015 | B12: Regular Air | C12: 3.4 | D12: Manitoba | E12: Small Pack
A13: 1016 | B13: Regular Air | C13: 4.4 | D13: Quebec | E13: Wrap Bag
... A2000: 3003 | B2000: Delivery Truck | C2000: 31.1 | D2000: Saskachewan | E2000: Jumbo Box
